---
layout: post
title: 一次生产问题的惨痛经历
author: itsxun
date: 2018-06-12 14:43:41 +0800
catalog: true
tags:
    - bug纪实
---

# 发现阶段
> 新版本发布后，在第二天中午收到了系统对DB的监控告警。里面的告警内容是一个java异常

```py
java.util.NoSuchElementException
at java.util.ArrayList$Itr.next(ArrayList.java.854)
at org.apache.ibatis.scripting.xmltags.ForEachSqlNode.apply(ForEachSqlNode.java.62)
...
# java版本是JDK8
```

# 定位阶段

根据错误信息我找到了报错的sql, 大概是这样的:
```xml
<insert id='XXX'>
  <foreach item="myItem" collections="myCollec">
     insert into XXX
  </foreach>  
</insert>
```

这个时候其实错误就很明显了，肯定是foreach循环的问题，但是为什么对List循环会抛出NoSuchElementException，需要先看看源码

```java
public class ArrayList<E> extends AbstractList<E>
        implements List<E>, RandomAccess, Cloneable, java.io.Serializable {

    transient Object[] elementData;//实际存储数据的数组

    private int size;//数组大小

    private class Itr implements Iterator<E> {
        int cursor;       // index of next element to return
        public E next() {
            checkForComodification();
            int i = cursor;
            if (i >= size)
                throw new NoSuchElementException();//在这里抛出了异常
            Object[] elementData = ArrayList.this.elementData;
            if (i >= elementData.length)
                throw new ConcurrentModificationException();
            cursor = i + 1;
            return (E) elementData[lastRet = i];
        }
    }
}
```
这里可以分析一下，i指的是下一个元素的position，size指的是ArrayList中对数组长度的记录。当需要取出的元素position大于list的size的时候，会抛出异常NoSuchElementException.
顺便可以看出来，mybatis的foreach是用迭代器实现的。

起码有了突破口了，问题应该就出在传进来的list上面，于是我猜想会不会是list为null，虽然抛的不是空指针。

继续跟了下代码，传参是这样的。
```java
xxxMapper.insert(ImmutableMap.of("myCollec",list));
```

> ImmutableMap是google开源的guava中的一个Map类，禁止value为null，否则抛异常。

所以参数为null的情况是不存在的。于是我又想到，如果传进去一个空的List会怎么样。

所以我把mapper调用处的参数换成new一个list，debug一下，发现sql语句根本没跑，就更不可能有抛异常的情况了。

我在日志平台搜了下，找到了两条记录。看了一下DB，新增了将近1000条记录，加上测试中确定是没有出现过这种情况，说明这个问题较难复现，是小概率问题。

正当我一筹莫展之际，我看到日志上，在这个异常上方，还有一条java代码报错
```java
java.lang.ArrayIndexOutOfBoundsException: -1
at java.util.ArrayList.fastRemove(ArrayList.java:546)
...
```

这个是数组越界错误，生产上的异常自然是都不能放过的，所以我继续搜了一下这条异常，也是两条，更奇怪的是每一次出现都刚好是在那个NoSuchElementException正前面，说明这两条异常，肯定是互相联系的！

根据数组越界的报错提示，我找到了报错的java代码，在一个异步方法中
```java
list.remove(obj);
```

貌似看不出什么，点进去跟一下源码看下
```java
private void fastRemove(int index) {
    modCount++;
    int numMoved = size - index - 1;
    if (numMoved > 0)
        System.arraycopy(elementData, index+1, elementData, index, numMoved);
    elementData[--size] = null; // clear to let GC do its work
}
```

remove完后置为null，让gc回收掉，既然是数组越界问题应该就出在--size上面了。
返回去，找了下，用于remove操作的list是从另外一个方法中传进来的，找了下传进来的源头，发现这个list在传递给异步方法，并且经过几行代码后，又remove了一次，并且是remove的同一个obj，然后调用了抛出NoSuchElementException的mapper方法！

```
//主方法逻辑
异步方法(list);
...                   
list.remove(obj);     
mapper.insert(list);    

-------------

//异步方法里面
list.remove(obj);  
```

结合后面的mapper方法的NoSuchElementException，我猜想，会不会是list在被mapper遍历的时候，异步方法remove了，类似于并发修改那样子，代码就抛出异常了。似乎解释得通，但是mapper在遍历之前就已经remove过一次了，异步方法的remove根本就不会对list造成影响，自然不会影响遍历。

考虑到两个方法是并发的，所以不知道具体的执行顺序，但是我理解remove操作是幂等的，不管remove多少次，之后的结果都是一样的，并且也不会抛出越界的异常，这时候同事提醒我，一个一个remove肯定不会有问题，但是如果并发的remove就可能会有问题。

我准备写个demo测试一下
```java
public class Test {
    public static void main(String[] args) throws Exception {
        List list = new ArrayList<>();
        list.add("a");
        while (true) {
            CountDownLatch c = new CountDownLatch(1);
            MyThread t1 = new MyThread("t1", c, list);
            MyThread t2 = new MyThread("t2", c, list);
            t1.start();
            t2.start();
            c.countDown();
        }
    }
}

class MyThread extends Thread {
    private String name;
    private CountDownLatch c;
    private List list;

    public MyThread(String name, CountDownLatch c, List list) {
        setName(name);
        this.c = c;
        this.list = list;
    }

    @Override
    public void run() {
        try {
            c.await();
        } catch (InterruptedException e) {}
        System.out.println(getName() + "准备remove");
        try {
            list.remove("a");
        } catch (Exception e) {
            e.printStackTrace();
            System.exit(-1);
        }
    }
}
```

刚跑，方法就停了，看了下，报的错误正是数组越界，指向remove的那一行。所以猜想是成立的。

所以基本上可以确定，因为主方法中的remove和异步方法的remove并发执行了，说的再简单点，就是两处同时进去了remove方法，由于主方法先执行，--size先进行，所以当异步方法准备--size的时候就抛出异常了。
查了一下库。list中应该就会只有一个元素，也间接的证实了结论。

那么，继续跟问题，mapper的foreach循环为什么会抛出NoSuchElementException。

我理解，当list为空的时候，迭代器是不会抛异常的，但是目前的场景中，list在foreach的时候里面就是空的，所以应该不会报错才对。

继续看着remove的这行代码
```java
  elementData[--size] = null; // clear to let GC do its work
```
我突然想到，会不会是异步方法在--size完后，虚拟机检查到数组越界了，所以抛出数组越界异常，但是size还是减下去了，变成了-1！但是主方法正常在跑，这样迭代器在迭代时候，由于size为-1，当然就不可能在list中找到下一个元素的位置。

所以我又写了个demo准备测试下
```java
public class Test {
    public static void main(String[] args) throws Exception {
        List list = new ArrayList<>();
        list.add("a");
        while (true) {
            CountDownLatch c = new CountDownLatch(1);
            MyThreadA t1 = new MyThreadA("t1", c, list);
            MyThreadB t2 = new MyThreadB("t2", c, list);
            t1.start();
            t2.start();
            Thread.currentThread().sleep(10);//让线程各就各位
            c.countDown();
        }
    }
}

class MyThreadA extends Thread {
    private CountDownLatch c;
    private List list;

    public MyThreadA(String name, CountDownLatch c, List list) {
        setName(name);
        this.c = c;
        this.list = list;
    }

    @Override
    public void run() {
        try {
            c.await();
        } catch (InterruptedException e) {
        }
        try {
            list.remove("a");
            for(Object o:list){
                System.out.println(o.toString());
            }
        } catch (Exception e) {
            System.out.println("size:"+list.size());
            e.printStackTrace();
            System.exit(-1);
        }
    }
}
class MyThreadB extends Thread {
    private CountDownLatch c;
    private List list;

    public MyThreadB(String name, CountDownLatch c, List list) {
        setName(name);
        this.c = c;
        this.list = list;
    }

    @Override
    public void run() {
        try {
            c.await();
        } catch (InterruptedException e) {}
        try {
            list.remove("a");
        } catch (Exception e) {
            e.printStackTrace();
        }
    }
}
```

运行了两次后，终于抛出了和生产一样的异常，并且size真的是-1!

```
size:-1
java.util.NoSuchElementException
	at java.util.ArrayList$Itr.next(ArrayList.java:862)
	at com.pingan.ela.MyThreadA.run(Test.java:51)
java.lang.ArrayIndexOutOfBoundsException: -1
	at java.util.ArrayList.fastRemove(ArrayList.java:550)
	at java.util.ArrayList.remove(ArrayList.java:533)
	at com.pingan.ela.MyThreadB.run(Test.java:77)

Process finished with exit code -1
```

## 收尾
事实上这个场景要复现其实概率会挺低的，因为主方法在remove之前还操作了一次DB，所以正好能和异步方法的remove并行的概率会很低，第一次告警后的一天里的log也能看出来，几乎没有复现的了。
线程安全问题不能忽视，这种问题包括我在内的很多开发其实是很清楚的，但是开发的时候还是会由于不小心，引用逃逸到其他线程，这次记录下来，也是提醒自己下次不再犯，共勉!
